Workbook
Name ml: ABBIndia!$J$6

Sheet Valuation
A2: Name of Target Company | D2: BHEL
C4: Industry | D4: Industry Multiple Range | F4: ="Implied EV-"&D2 -> Implied EV-BHEL | H4: Minority Interest | I4: Total Debt | K4: Cash & Cash Eq | L4: Investments | M4: ="Implied Equity-"&D2 -> Implied Equity-BHEL | O4: Diluted Shares O/S | P4: ="Implied Per Share Value-"&D2 -> Implied Per Share Value-BHEL
B5: Metrics | C5: Benchmark Multiple | D5: Lower | E5: Higher | F5: Lower | G5: Higher | M5: Lower | N5: Higher | P5: Lower | Q5: Higher
A7: FY1 EV/EBITDA | B7: =BHEL!L71 -> 20951 | C7: =Output!M16 -> 77.318423 | F7: =B7*C7 -> 1619898.3 | H7: =BHEL!F20 -> 0 | I7: =BHEL!E25 -> 88080 | J7: =SUM(BHEL!F28:F29) -> 4451.6 | K7: =BHEL!F30 -> 61574.7 | L7: =BHEL!F31 -> 2556.7 | M7: =F7-H7-I7-J7+K7+L7 -> 1591498.1 | O7: =BHEL!C17 -> 3482.0634 | P7: =M7/O7 -> 457.05604
A8: FY2 EV/EBITDA | B8: =BHEL!M71 -> 39844 | C8: =Output!R16 -> 61.192603 | F8: =B8*C8 -> 2438158.1 | H8: =BHEL!F21 -> 0 | I8: =BHEL!E25 -> 88080 | J8: =SUM(BHEL!F28:F29) -> 4451.6 | K8: =BHEL!F30 -> 61574.7 | L8: =BHEL!F31 -> 2556.7 | M8: =F8-H8-I8-J8+K8+L8 -> 2409757.9 | O8: =BHEL!C17 -> 3482.0634 | P8: =M8/O8 -> 692.04883
M10: =D2&" Valuation Range as per Trading Comps" -> BHEL Valuation Range as per Trading Comps
A14: ="Calculation of Diluted Shares-"&D2 -> Calculation of Diluted Shares-BHEL
A16: Basic Shares o/s
A17: Diluted Shares o/s
A20: ="Market Price Per Share-"&D2 -> Market Price Per Share-BHEL
A21: ESoPS/Warrants etc. Treasury Stock Method
C22: Exercise | E22: Notional | H22: Net
B23: O/S | C23: Price | D23: ITM? | E23: Shares Issued | F23: Cash | G23: Buyback | H23: Dilution
D24: =IF(C24<$D$20,"Yes","No") -> No | E24: =IF(D24="Yes",B24,0) -> 0 | F24: =E24*C24 -> 0 | G24: =IFERROR(F24/D20,0) -> 0 | H24: =E24-G24 -> 0
D25: =IF(C25<$D$20,"Yes","No") -> No | E25: =IF(D25="Yes",B25,0) -> 0 | F25: =E25*C25 -> 0 | G25: =IFERROR(F25/D21,0) -> 0 | H25: =E25-G25 -> 0
H26: =SUM(H24:H25) -> 0
A29: RSUs
A30: Nature
B33: =SUM(B31:B32) -> 0
A35: Convertibles
E36: Conversion Price | F36: Share Dilution
A37: Nature | B37: Face Value | D37: BV/MV
F38: =IF(E38<$D$20,B38/E38,0) -> 0
F39: =IF(E39<$D$20,B39/E39,0) -> 0
F40: =SUM(F38:F39) -> 0

Sheet Output
A1: Comparable Company Analysis
A2: (All numbers are in millions except per share data)
A4: Industry | C4: Capital good manufacturing
A5: Geography | C5: INDIA
A6: Currency | C6: INR
B8: C10 | D8: F33 | E8: F18 | F8: F32 | G8: H65 | H8: H71 | I8: H69 | J8: H80 | L8: L65 | M8: L71 | N8: L69 | O8: L80 | Q8: M65 | R8: M71 | S8: M69 | T8: M80 | U8: O79
B9: Reported Currency | C9: Exchange Rate | G9: LTM Multiples | L9: FY1 Multiple | Q9: FY2 Multiple
A10: Peer Group Companies | D10: CMP | E10: Market Cap | F10: EV | G10: EV/Sales | H10: EV/EBITDA | I10: EV/EBIT | J10: P/E | L10: EV/Sales | M10: EV/EBITDA | N10: EV/EBIT | O10: P/E | Q10: EV/Sales | R10: EV/EBITDA | S10: EV/EBIT | T10: P/E | U10: Growth
A11: ABBIndia | B11: =INDIRECT($A11&"!"&B$8) -> INR | D11: =INDIRECT($A11&"!"&D$8) -> 9020 | E11: =INDIRECT($A11&"!"&E$8) -> 1911912.8 | F11: =INDIRECT($A11&"!"&F$8) -> 1864520.3 | G11: =$F11/INDIRECT($A11&"!"&G$8) -> 16.773801 | H11: =$F11/INDIRECT($A11&"!"&H$8) -> 105.36097 | I11: =$F11/INDIRECT($A11&"!"&I$8) -> 113.29029 | J11: =$D11/INDIRECT($A11&"!"&J$8) -> 130.68511 | L11: =$F11/INDIRECT($A11&"!"&L$8) -> 13.708751 | M11: =$F11/INDIRECT($A11&"!"&M$8) -> 86.051475 | N11: =$F11/INDIRECT($A11&"!"&N$8) -> 92.45861 | O11: =$D11/INDIRECT($A11&"!"&O$8) -> 107.03691 | Q11: =$F11/INDIRECT($A11&"!"&Q$8) -> 11.406445 | R11: =$F11/INDIRECT($A11&"!"&R$8) -> 71.215183 | S11: =$F11/INDIRECT($A11&"!"&S$8) -> 77.928627 | T11: =$D11/INDIRECT($A11&"!"&T$8) -> 89.234042
A12: Siemens | B12: =INDIRECT($A12&"!"&B$8) -> INR | D12: =INDIRECT($A12&"!"&D$8) -> 7790.3 | E12: =INDIRECT($A12&"!"&E$8) -> 2774283.6 | F12: =INDIRECT($A12&"!"&F$8) -> 2704097.1 | G12: =$F12/INDIRECT($A12&"!"&G$8) -> 12.721571 | H12: =$F12/INDIRECT($A12&"!"&H$8) -> 98.650069 | I12: =$F12/INDIRECT($A12&"!"&I$8) -> 111.90602 | J12: =$D12/INDIRECT($A12&"!"&J$8) -> 119.66929 | L12: =$F12/INDIRECT($A12&"!"&L$8) -> 11.164267 | M12: =$F12/INDIRECT($A12&"!"&M$8) -> 83.400581 | N12: =$F12/INDIRECT($A12&"!"&N$8) -> 93.073022 | O12: =$D12/INDIRECT($A12&"!"&O$8) -> 100.03596 | Q12: =$F12/INDIRECT($A12&"!"&Q$8) -> 9.1124356 | R12: =$F12/INDIRECT($A12&"!"&R$8) -> 66.646877 | S12: =$F12/INDIRECT($A12&"!"&S$8) -> 76.060336 | T12: =$D12/INDIRECT($A12&"!"&T$8) -> 81.043433
A13: CGPower | B13: =INDIRECT($A13&"!"&B$8) -> INR | D13: =INDIRECT($A13&"!"&D$8) -> 688.9 | E13: =INDIRECT($A13&"!"&E$8) -> 1053186.8 | F13: =INDIRECT($A13&"!"&F$8) -> 1039408.3 | G13: =$F13/INDIRECT($A13&"!"&G$8) -> 12.918356 | H13: =$F13/INDIRECT($A13&"!"&H$8) -> 92.140412 | I13: =$F13/INDIRECT($A13&"!"&I$8) -> 100.60283 | J13: =$D13/INDIRECT($A13&"!"&J$8) -> 125.17445 | L13: =$F13/INDIRECT($A13&"!"&L$8) -> 10.572225 | M13: =$F13/INDIRECT($A13&"!"&M$8) -> 71.236265 | N13: =$F13/INDIRECT($A13&"!"&N$8) -> 77.021738 | O13: =$D13/INDIRECT($A13&"!"&O$8) -> 97.564084 | Q13: =$F13/INDIRECT($A13&"!"&Q$8) -> 8.548469 | R13: =$F13/INDIRECT($A13&"!"&R$8) -> 55.738328 | S13: =$F13/INDIRECT($A13&"!"&S$8) -> 60.681204 | T13: =$D13/INDIRECT($A13&"!"&T$8) -> 75.512441
A14: BHEL | B14: =INDIRECT($A14&"!"&B$8) -> INR | D14: =INDIRECT($A14&"!"&D$8) -> 305.65 | E14: =INDIRECT($A14&"!"&E$8) -> 1064292.7 | F14: =INDIRECT($A14&"!"&F$8) -> 1092692.9 | G14: =$F14/INDIRECT($A14&"!"&G$8) -> 4.5733182 | H14: =$F14/INDIRECT($A14&"!"&H$8) -> 178.36971 | I14: =$F14/INDIRECT($A14&"!"&I$8) -> 300.43796 | J14: =$D14/INDIRECT($A14&"!"&J$8) -> 377.34568 | L14: =$F14/INDIRECT($A14&"!"&L$8) -> 3.4530698 | M14: =$F14/INDIRECT($A14&"!"&M$8) -> 52.154688 | N14: =$F14/INDIRECT($A14&"!"&N$8) -> 59.99851 | O14: =$D14/INDIRECT($A14&"!"&O$8) -> 76.240958 | Q14: =$F14/INDIRECT($A14&"!"&Q$8) -> 2.7265449 | R14: =$F14/INDIRECT($A14&"!"&R$8) -> 27.424276 | S14: =$F14/INDIRECT($A14&"!"&S$8) -> 28.827143 | T14: =$D14/INDIRECT($A14&"!"&T$8) -> 37.692687
Z15: =#REF!*Y15+#REF! -> #REF!
F16: Median | G16: =MEDIAN(G11:G14) -> 12.819963 | H16: =MEDIAN(H11:H14) -> 102.00552 | I16: =MEDIAN(I11:I14) -> 112.59816 | J16: =MEDIAN(J11:J14) -> 127.92978 | K16: =MEDIAN(K11:K14) -> #NUM! | L16: =MEDIAN(L11:L14) -> 10.868246 | M16: =MEDIAN(M11:M14) -> 77.318423 | N16: =MEDIAN(N11:N14) -> 84.740174 | ... T16: =MEDIAN(T11:T14) -> 78.277937
F17: 25th Percentile
F18: 75th Percentile
H22: Calculated LTM Based and forward based Multiples
A25: 1) How to select right multiple to compate (should we compare EV/Sales or EV/EBITDA or EV/EBIT or P/E)
A27: EV/Sales | C27: All industries which are in early growth stage and we have losses in most of the companies because of high costt of technology, customer acquisition etc,
C28: App based companies like Ola, Uber, Zomato
A30: P/E | C30: This multiple has many limitations, such as
C31: 1) It is impacted by Non operating items of Income as well as expense | L31: Since net profit is taken, it considers both non operating and non recurring items
C32: 2) It may be distorted by differences in financial leverage amongst comp companies | L32: Companies having debt, may show lower PE making us to believe its underpriced
C33: P/E multiple has special use for banking companies as in Banking industry , interest exp is one of the operating expense. Therefore, EBIT doesn't represent true picture of profitability of Banking companies. We can calculate profits only after deducting interest expense which is net income
A36: EV/EBIT | C36: This multiple represents better picture of comparison compared to EV/Sales or P/E Multiples
C37: 1) Compared to EV/Sales multiple, EV/EBIT multiple presents better picture of comparison as it captures profitability of the business
C38: 2) EV/EBIT multiple focuses on core profit of business compared to P/E multiple which is impacted by both operating as well as non operating profits and expenses | T38: Even EV considers only operating items, as it excludes non operating investments and cash
C39: 3) Not impacted by differences in financial leverage of comparable companies
C40: Most popularly used for profit making companies
A43: EV/EBITDA | C43: If D&A expenses are not distorting EBIT of comp companies, EV/EBIT and EV/EBITDA will give almost same valuation.
C44: if presence of D&A expenses is distorting picture of profitability of comp companies then EV/EBITDA multiple will give better comparison, especially in case of Capital intensive industries
A47: EV/EBITDAR | C47: EBITDAR represents Earnings before interest, tax ,D&A and lease rental expenses
C48: This multiple has special use in case of aircraft industries where operating lease rental expenses could be substantial and EBITDA could present distorted picture of profitability on comparable basis due to difference in treatment of D&A exp and rental exp in calculation of EBITDA, therefore for such industries we compare EBITDAR multiple to give equal treatment to their D&A and rental exp.
A54: 2) LTM Vs Forward Multiple
C55: Normally bankers prefer forward based multiples over LTM based multiples to compare current valuation in the market. The reason being current market price of a particular company is more influenced by what company is likely to deliver in near future than LTM performance, so we get better picture of comparison the basis of forward multiples than LTM multiples
C59: However if reliable estimates are not available, then we can give preference to LTM multiples over forward multiples
C61: Please note that under both LTM as well as forward multiples, we are comparing current market price of comp companies

Sheet Input
A1: Company Name
A2: ="(In "&C10&" Millions Except Per Share Data)" -> (In Millions Except Per Share Data)
A4: Basic Details
A5: Analyst Name
A6: Updation Date
A7: Ticker
A8: Latest Annual
A9: Latest Quarter
A10: Reported Currency
A11: Tax Rate
A14: Enterprise Value | C14: Class A | D14: Class B | E14: Class C
A15: Per Share Price
A16: Shares Outstanding Basic
A17: Shares Outstanding Diluted | C17: =C16+I45 -> #DIV/0!
A18: Market Cap | C18: =C15*C17 -> #DIV/0!
C19: BV of MI | D19: P/B | E19: MV of MI
A20: + Minority Interest | H20: 2 | O20: BV of MI
A21: + Pref. Share Capital | E21: BV/MV of Pref | O21: MV of MI
B22: Total Pref. Capital
B23: Less: Convertible Pref Capital | O23: BV of Pref
A24: + Debt | E24: BV/MV of Debt | O24: MV of Pref
B25: Total Debt (Including Capital Lease)
B26: Less: Convertible Debt | O26: BV of Debt
A27: + Debt Equivalents | O27: MV of Debt
B28: Unfunded Pension Obligations | G28: Net defined benefit liability | I28: DBO(-)PA | J28: treated as debt as interest to be accrued over liability
B29: Capitalised Value of Operating Lease | G29: we are showing assets taken on operating lease as ROU asset and lease liability to be recognised | O29: Capitalised
A30: - Cash & Cash Equivalents | O30: Not Capitalised
A31: - Non Operating Assets
A32: Enterprise Value
A33: Weighted Average Share Price of All Classes of Share
A35: Calculation of Dilution
B37: ESOPS/Warrants-Treasury Stock Method
C38: Units Outstanding | D38: Exercise | F38: Notional | I38: Net
D39: Price | E39: ITM? | F39: Shares Issued | G39: Cash | H39: Buyback | I39: Dilution
B40: Grant 1 | F40: =IF(E40="INTM",C40,0) -> 0 | G40: =F40*D40 -> 0 | H40: =G40/$C$15 -> #DIV/0! | I40: =F40-H40 -> #DIV/0!
B41: Grant 2 | F41: =IF(E41="INTM",C41,0) -> 0 | G41: =F41*D41 -> 0 | H41: =G41/$C$15 -> #DIV/0! | I41: =F41-H41 -> #DIV/0!
B42: Grant 3 | F42: =IF(E42="INTM",C42,0) -> 0 | G42: =F42*D42 -> 0 | H42: =G42/$C$15 -> #DIV/0! | I42: =F42-H42 -> #DIV/0!
B43: Grant 4 | F43: =IF(E43="INTM",C43,0) -> 0 | G43: =F43*D43 -> 0 | H43: =G43/$C$15 -> #DIV/0! | I43: =F43-H43 -> #DIV/0!
B44: Grant 5 | F44: =IF(E44="INTM",C44,0) -> 0 | G44: =F44*D44 -> 0 | H44: =G44/$C$15 -> #DIV/0! | I44: =F44-H44 -> #DIV/0!
I45: =SUM(I40:I44) -> #DIV/0!
...

Sheet ABBIndia
A1: Company Name
A2: ="(In "&C10&" Millions Except Per Share Data)" -> (In INR Millions Except Per Share Data)
A4: Basic Details
A5: Analyst Name | C5: Kiran
A6: Updation Date | C6: 45457 | J6: 1000000
A7: Ticker | C7: ABB
A8: Latest Annual | C8: 45291 | D8: Date of latest anuual report
A9: Latest Quarter | C9: 45382 | D9: Date of latest Quarterly report
A10: Reported Currency | C10: INR
A11: Tax Rate | C11: =30%*1.12*1.04 -> 0.34944 | D11: 12% surcharge, HEC 4%
A14: Enterprise Value | C14: Class A | D14: Class B | E14: Class C
A15: Per Share Price | C15: 9020
A16: Shares Outstanding Basic | C16: =211908375/ml -> 211.90838
A17: Shares Outstanding Diluted | C17: =C16+I45+C53+F60 -> 211.96373 | G17: B.V of Equity | H17: MV/BV
A18: Market Cap | C18: =C15*C17 -> 1911912.8 | F18: =SUM(C18:E18) -> 1911912.8 | G18: 59446 | H18: =F18/G18 -> 32.162178
C19: BV of MI | D19: P/B | E19: MV of MI
A20: + Minority Interest | C20: 0 | D20: 0 | E20: 0 | F20: =SUM(C20:E20) -> 0 | H20: 2 | O20: BV of MI
A21: + Pref. Share Capital | E21: BV/MV of Pref | O21: MV of MI
B22: Total Pref. Capital
B23: Less: Convertible Pref Capital | F23: =E22-E23 -> 0 | O23: BV of Pref
A24: + Debt | E24: BV/MV of Debt | O24: MV of Pref
B25: Total Debt (Including Capital Lease) | E25: =28.2*10 -> 282
B26: Less: Convertible Debt | F26: =E25-E26 -> 282 | O26: BV of Debt
A27: + Debt Equivalents | O27: MV of Debt
B28: Unfunded Pension Obligations | F28: =1.3*10 -> 13
B29: Capitalised Value of Operating Lease | F29: =(20.05+28.93)*10 -> 489.8 | O29: Capitalised
A30: - Cash & Cash Equivalents | F30: =(876.88+3939.29)*10 -> 48161.7 | O30: Not Capitalised
A31: - Non Operating Assets | F31: =1.56*10 -> 15.6
A32: Enterprise Value | F32: =F18+F20+F23+F26+F29-F30-F31+F28 -> 1864520.3
A33: Weighted Average Share Price of All Classes of Share | F33: =F18/SUM(C17:E17) -> 9020
A35: Calculation of Dilution
B37: ESOPS/Warrants-Treasury Stock Method
C38: Units Outstanding | D38: Exercise | F38: Notional | I38: Net
D39: Price | E39: ITM? | F39: Shares Issued | G39: Cash | H39: Buyback | I39: Dilution
B40: Grant 1 | F40: =IF(E40="INTM",C40,0) -> 0 | G40: =F40*D40 -> 0 | H40: =G40/$C$15 -> 0 | I40: =F40-H40 -> 0
B41: Grant 2 | F41: =IF(E41="INTM",C41,0) -> 0 | G41: =F41*D41 -> 0 | H41: =G41/$C$15 -> 0 | I41: =F41-H41 -> 0
B42: Grant 3 | F42: =IF(E42="INTM",C42,0) -> 0 | G42: =F42*D42 -> 0 | H42: =G42/$C$15 -> 0 | I42: =F42-H42 -> 0
B43: Grant 4 | F43: =IF(E43="INTM",C43,0) -> 0 | G43: =F43*D43 -> 0 | H43: =G43/$C$15 -> 0 | I43: =F43-H43 -> 0
B44: Grant 5 | F44: =IF(E44="INTM",C44,0) -> 0 | G44: =F44*D44 -> 0 | H44: =G44/$C$15 -> 0 | I44: =F44-H44 -> 0
I45: =SUM(I40:I44) -> 0
...

Sheet Siemens
A1: Company Name
A2: ="(In "&C10&" Millions Except Per Share Data)" -> (In INR Millions Except Per Share Data)
A4: Basic Details
A5: Analyst Name | C5: Kiran
A6: Updation Date | C6: 45457
A7: Ticker | C7: Siemens
A8: Latest Annual | C8: 45199
A9: Latest Quarter | C9: 45382
A10: Reported Currency | C10: INR
A11: Tax Rate | C11: =30%*1.12*1.04 -> 0.34944
A14: Enterprise Value | C14: Class A | D14: Class B | E14: Class C
A15: Per Share Price | C15: 7790.3
A16: Shares Outstanding Basic | C16: =356120255/ml -> 356.12025
A17: Shares Outstanding Diluted | C17: =C16+I45+C53+F60 -> 356.12025 | G17: BV | H17: MV/BV
A18: Market Cap | C18: =C15*C17 -> 2774283.6 | F18: =SUM(C18:E18) -> 2774283.6 | G18: 139165 | H18: =F18/G18 -> 19.935211
C19: BV of MI | D19: P/B | E19: MV of MI
A20: + Minority Interest | C20: 86 | D20: =H18 -> 19.935211 | E20: =C20*D20 -> 1714.4281 | F20: =CHOOSE(H20,C20,E20) -> 1714.4281 | G20: BV | H20: 2 | O20: BV of MI
A21: + Pref. Share Capital | E21: BV/MV of Pref | O21: MV of MI
B22: Total Pref. Capital
B23: Less: Convertible Pref Capital | O23: BV of Pref
A24: + Debt | E24: BV/MV of Debt | O24: MV of Pref
B25: Total Debt (Including Capital Lease)
B26: Less: Convertible Debt | F26: 0 | O26: BV of Debt
A27: + Debt Equivalents | O27: MV of Debt
B28: Unfunded Pension Obligations | F28: =478+221+2653+110 -> 3462
B29: Capitalised Value of Operating Lease | F29: =992+834 -> 1826 | O29: Capitalised
A30: - Cash & Cash Equivalents | F30: =17217+59308 -> 76525 | O30: Not Capitalised
A31: - Non Operating Assets | F31: =647+14+3 -> 664
A32: Enterprise Value | F32: =F18+F20+F23+F26+F29-F30-F31+F28 -> 2704097.1
A33: Weighted Average Share Price of All Classes of Share | F33: =F18/SUM(C17:E17) -> 7790.3
A35: Calculation of Dilution
B37: ESOPS/Warrants-Treasury Stock Method
C38: Units Outstanding | D38: Exercise | F38: Notional | I38: Net
D39: Price | E39: ITM? | F39: Shares Issued | G39: Cash | H39: Buyback | I39: Dilution
B40: Grant 1 | F40: =IF(E40="INTM",C40,0) -> 0 | G40: =F40*D40 -> 0 | H40: =G40/$C$15 -> 0 | I40: =F40-H40 -> 0
B41: Grant 2 | F41: =IF(E41="INTM",C41,0) -> 0 | G41: =F41*D41 -> 0 | H41: =G41/$C$15 -> 0 | I41: =F41-H41 -> 0
B42: Grant 3 | F42: =IF(E42="INTM",C42,0) -> 0 | G42: =F42*D42 -> 0 | H42: =G42/$C$15 -> 0 | I42: =F42-H42 -> 0
B43: Grant 4 | F43: =IF(E43="INTM",C43,0) -> 0 | G43: =F43*D43 -> 0 | H43: =G43/$C$15 -> 0 | I43: =F43-H43 -> 0
B44: Grant 5 | F44: =IF(E44="INTM",C44,0) -> 0 | G44: =F44*D44 -> 0 | H44: =G44/$C$15 -> 0 | I44: =F44-H44 -> 0
I45: =SUM(I40:I44) -> 0
...

Sheet CGPower
A1: Company Name
A2: ="(In "&C10&" Millions Except Per Share Data)" -> (In INR Millions Except Per Share Data)
A4: Basic Details
A5: Analyst Name | C5: Kiran
A6: Updation Date | C6: 45457
A7: Ticker | C7: CGPower
A8: Latest Annual | C8: 45016
A9: Latest Quarter | C9: 45382
A10: Reported Currency | C10: INR
A11: Tax Rate | C11: =30%*1.12*1.04 -> 0.34944
A14: Enterprise Value | C14: Class A | D14: Class B | E14: Class C
A15: Per Share Price | C15: 688.9
A16: Shares Outstanding Basic | C16: =1527131434/ml -> 1527.1314
A17: Shares Outstanding Diluted | C17: =C16+I45+C53+F60 -> 1528.7949 | G17: B.V | H17: P/B
A18: Market Cap | C18: =C15*C17 -> 1053186.8 | F18: =SUM(C18:E18) -> 1053186.8 | G18: =3017.44*10 -> 30174.4 | H18: =F18/G18 -> 34.903323
C19: BV of MI | D19: P/B | E19: MV of MI
A20: + Minority Interest | C20: =1.33*10 -> 13.3 | D20: =H18 -> 34.903323 | E20: =C20*D20 -> 464.2142 | F20: =CHOOSE(H20,C20,E20) -> 464.2142 | G20: B.V | H20: 2 | O20: BV of MI
A21: + Pref. Share Capital | E21: BV/MV of Pref | O21: MV of MI
B22: Total Pref. Capital
B23: Less: Convertible Pref Capital | F23: 0 | O23: BV of Pref
A24: + Debt | E24: BV/MV of Debt | O24: MV of Pref
B25: Total Debt (Including Capital Lease)
B26: Less: Convertible Debt | F26: 0 | O26: BV of Debt
A27: + Debt Equivalents | O27: MV of Debt
B28: Unfunded Pension Obligations | F28: =10.06*10 -> 100.6
B29: Capitalised Value of Operating Lease | F29: =(11.91+5.53)*10 -> 174.4 | O29: Capitalised
A30: - Cash & Cash Equivalents | F30: =(199.84+654.57)*10 -> 8544.1 | O30: Not Capitalised
A31: - Non Operating Assets | F31: =(0.75+587.7+73.18-64.27)*10 -> 5973.6
A32: Enterprise Value | F32: =F18+F20+F23+F26+F29-F30-F31+F28 -> 1039408.3
A33: Weighted Average Share Price of All Classes of Share | F33: =F18/SUM(C17:E17) -> 688.9
A35: Calculation of Dilution
B37: ESOPS/Warrants-Treasury Stock Method
C38: Units Outstanding | D38: Exercise | F38: Notional | I38: Net
D39: Price | E39: ITM? | F39: Shares Issued | G39: Cash | H39: Buyback | I39: Dilution
B40: Grant 1 | C40: =783260/ml -> 0.78326 | D40: 156.2 | E40: =IF(D40<$C$15,"INTM","OTM") -> INTM | F40: =IF(E40="INTM",C40,0) -> 0.78326 | G40: =F40*D40 -> 122.34521 | H40: =G40/$C$15 -> 0.17759502 | I40: =F40-H40 -> 0.60566498
B41: Grant 2 | C41: =317120/ml -> 0.31712 | D41: 156.2 | E41: =IF(D41<$C$15,"INTM","OTM") -> INTM | F41: =IF(E41="INTM",C41,0) -> 0.31712 | G41: =F41*D41 -> 49.534144 | H41: =G41/$C$15 -> 0.071903243 | I41: =F41-H41 -> 0.24521676
B42: Grant 3 | C42: =339480/ml -> 0.33948 | D42: 156.2 | E42: =IF(D42<$C$15,"INTM","OTM") -> INTM | F42: =IF(E42="INTM",C42,0) -> 0.33948 | G42: =F42*D42 -> 53.026776 | H42: =G42/$C$15 -> 0.076973111 | I42: =F42-H42 -> 0.26250689
B43: Grant 4 | C43: =339480/ml -> 0.33948 | D43: 156.2 | E43: =IF(D43<$C$15,"INTM","OTM") -> INTM | F43: =IF(E43="INTM",C43,0) -> 0.33948 | G43: =F43*D43 -> 53.026776 | H43: =G43/$C$15 -> 0.076973111 | I43: =F43-H43 -> 0.26250689
B44: Grant 5 | C44: =453140/ml -> 0.45314 | D44: 251.65 | E44: =IF(D44<$C$15,"INTM","OTM") -> INTM | F44: =IF(E44="INTM",C44,0) -> 0.45314 | G44: =F44*D44 -> 114.03268 | H44: =G44/$C$15 -> 0.16552864 | I44: =F44-H44 -> 0.28761136
I45: =SUM(I40:I44) -> 1.6635069
...

Sheet BHEL
A1: Company Name
A2: ="(In "&C10&" Millions Except Per Share Data)" -> (In INR Millions Except Per Share Data)
A4: Basic Details
A5: Analyst Name | C5: Kiran
A6: Updation Date | C6: 45457
A7: Ticker | C7: BHEL
A8: Latest Annual | C8: 45016
A9: Latest Quarter | C9: 45382
A10: Reported Currency | C10: INR
A11: Tax Rate | C11: =30%*1.12*1.04 -> 0.34944
A14: Enterprise Value | C14: Class A | D14: Class B | E14: Class C
A15: Per Share Price | C15: 305.65
A16: Shares Outstanding Basic | C16: =3482063355/ml -> 3482.0634
A17: Shares Outstanding Diluted | C17: =C16+I45+C53+F60 -> 3482.0634 | G17: BV | H17: P/BV
A18: Market Cap | C18: =C15*C17 -> 1064292.7 | F18: =SUM(C18:E18) -> 1064292.7 | G18: =(696.41+23742.24)*10 -> 244386.5 | H18: =F18/G18 -> 4.3549569
C19: BV of MI | D19: P/B | E19: MV of MI
A20: + Minority Interest | F20: 0 | H20: 2 | O20: BV of MI
A21: + Pref. Share Capital | E21: BV/MV of Pref | O21: MV of MI
B22: Total Pref. Capital
B23: Less: Convertible Pref Capital | F23: 0 | O23: BV of Pref
A24: + Debt | E24: BV/MV of Debt | O24: MV of Pref
B25: Total Debt (Including Capital Lease) | E25: =8808*10 -> 88080
B26: Less: Convertible Debt | F26: =E25-E26 -> 88080 | O26: BV of Debt
A27: + Debt Equivalents | O27: MV of Debt
B28: Unfunded Pension Obligations | F28: =396.7*10 -> 3967
B29: Capitalised Value of Operating Lease | F29: =(23.55+24.91)*10 -> 484.6 | O29: Capitalised
A30: - Cash & Cash Equivalents | F30: =(1835.04+4322.43)*10 -> 61574.7 | O30: Not Capitalised
A31: - Non Operating Assets | F31: =(254.48+1.19)*10 -> 2556.7
A32: Enterprise Value | F32: =F18+F20+F23+F26+F29-F30-F31+F28 -> 1092692.9
A33: Weighted Average Share Price of All Classes of Share | F33: =F18/SUM(C17:E17) -> 305.65
A35: Calculation of Dilution
B37: ESOPS/Warrants-Treasury Stock Method
C38: Units Outstanding | D38: Exercise | F38: Notional | I38: Net
D39: Price | E39: ITM? | F39: Shares Issued | G39: Cash | H39: Buyback | I39: Dilution
B40: Grant 1 | F40: =IF(E40="INTM",C40,0) -> 0 | G40: =F40*D40 -> 0 | H40: =G40/$C$15 -> 0 | I40: =F40-H40 -> 0
B41: Grant 2 | F41: =IF(E41="INTM",C41,0) -> 0 | G41: =F41*D41 -> 0 | H41: =G41/$C$15 -> 0 | I41: =F41-H41 -> 0
B42: Grant 3 | F42: =IF(E42="INTM",C42,0) -> 0 | G42: =F42*D42 -> 0 | H42: =G42/$C$15 -> 0 | I42: =F42-H42 -> 0
B43: Grant 4 | F43: =IF(E43="INTM",C43,0) -> 0 | G43: =F43*D43 -> 0 | H43: =G43/$C$15 -> 0 | I43: =F43-H43 -> 0
B44: Grant 5 | F44: =IF(E44="INTM",C44,0) -> 0 | G44: =F44*D44 -> 0 | H44: =G44/$C$15 -> 0 | I44: =F44-H44 -> 0
I45: =SUM(I40:I44) -> 0
...

Sheet Sheet1
C2: Mcap | D2: EV
B3: ABB | C3: =ABBIndia!F18 -> 1911912.8 | D3: =ABBIndia!F32 -> 1864520.3
B4: CG | C4: =CGPower!F18 -> 1053186.8 | D4: =CGPower!F32 -> 1039408.3
B5: BHEL | C5: =BHEL!F18 -> 1064292.7 | D5: =BHEL!F32 -> 1092692.9
B6: Siemens | C6: =Siemens!F18 -> 2774283.6 | D6: =Siemens!F32 -> 2704097.1

Sheet Source of Info
B2: Information Item | C2: Source | D2: Date | E2: Searching Key Words
B4: Enterprise Value
B6: Per Share Market Price | C6: Market Portal | D6: As on Updation Date
B8: Basic Shares Outstanding | C8: Latest Financial Report Published by Co Till Updation Date -In Case of US Co; On First page of 10K and 10Q - in Case of Non US Company, Notes to Accounts | D8: As Latest as possible on Updation Date
B10: Dilution
B11: 1. ESoPS/RSUs/PSU etc. | C11: Latest Financial Report Published by Co Till Updation Date Note 1 If Latest financial report is Quarterly Filing, then there are chances that you may not find comlete info about dilution into in Quarterly report, in that case you may refer latest available annual report published by co till updation date. Note 2 Information about dilution would be disclosed by the co in notes to accounts | D11: 1. Latest Financial Report available on updation date. 2. In Case complete infor not available in latest report due to quarterly filing, then you may refer latest annual report available | E11: 1. Forfeited 2. Nonvested
B12: 2. Warrants | E12: Warrants
B13: 3. Convertible Debt | E13: Convertible
B14: 4. Convertible Pref Shares | E14: Convertible
B16: Minority Interest | C16: From Balance Sheet | D16: Latest Available on Updation Date
B18: Pref. Share Capital | C18: From Balance Sheet | D18: Latest Available on Updation Date
B20: Debt | C20: From Balance Sheet | D20: Latest Available on Updation Date
B22: Cash & Cash Equivalents | C22: From Balance Sheet | D22: Latest Available on Updation Date
B24: Non Operating Assets | C24: From Balance Sheet | D24: Latest Available on Updation Date
B26: Unfunded Pension Obligations | C26: Notest to Accounts | D26: Should be from Latest availbale Financial report. But in case latest is quarterly then you would have to refer annual as this info will not be availbale in quarterly report | E26: Plan Assets
B28: Key Financials
B30: LTM Revenue | C30: Income Statement - Annual and Quarterly Report Published by Company | D30: Latest Annual and Quarterly Report Published by Company till Updation Date -In Case no Quarterly filing post annual filing, Only Annual filing - in Case Quarterly filing published post latest Annual filing, both latest annual and quarterly filing would be required
B32: LTM Operating Income/EBIT | C32: Income Statement - Annual and Quarterly Report Published by Company | D32: In Respective Annual and Quarterly Filings
B34: Cleaning of Reported Numbers | D34: In Respective Annual and Quarterly Filings | E34: Non-GAAP, Comparability | F34: GAAP vs Non GAAP Recon | I34: MD&A
B36: Depreciation and Amortisation | C36: Cash Flow Statement - Annual and Quarterly Report Published by Company | D36: In Respective Annual and Quarterly Filings
B38: LTM Net Income (Before Minority Interest Share) | C38: Income Statement - Annual and Quarterly Report Published by Company | D38: In Respective Annual and Quarterly Filings
B40: Weighted Average No. of Diluted Shares Outstyanding | C40: Income Statement or Notes to Accounts - Annual and Quarterly Report Published by Company | D40: In Respective Annual and Quarterly Filings
B42: Consensus Estimates | C42: Capital IQ Bloomberg MarketScreener

Sheet List of Peers
B2: India
B3: Large Cap
B4: Industrial goods manufacturing companies
A6: 1 | B6: POLYCAB INDIA LIMITED INR | C6: Exclude
A7: 2 | B7: ABB INDIA LIMITED INR
A8: 3 | B8: SIEMENS LIMITED INR
A9: 4 | B9: BHARAT ELECTRONICS LIMITED INR | C9: Exclude
A10: 5 | B10: HINDUSTAN AERONAUTICS LIMITED INR | C10: Exclude
A11: 6 | B11: HAVELLS INDIA LIMITED INR | C11: Exclude
A12: 7 | B12: CG POWER AND INDUSTRIAL SOLUTIONS.. INR
A13: 8 | B13: BHARAT HEAVY ELECTRICALS LIMITED I
B16: Final list of Comparables
A17: 1 | B17: ABB INDIA LIMITED INR
A18: 2 | B18: SIEMENS LIMITED INR
A19: 3 | B19: CG POWER AND INDUSTRIAL SOLUTIONS.. INR
A20: 4 | B20: BHARAT HEAVY ELECTRICALS LIMITED I
B23: Identify company which is most underpriced vs fair value based on trading comps technique
